*conda update --allを実行した際以下のようなエラーが発生した*
(base) C:\WINDOWS\system32>conda update --all
Solving environment: done

## Package Plan ##

  environment location: C:\ProgramData\Anaconda3


The following NEW packages will be INSTALLED:

    atomicwrites:             1.1.5-py36_0

The following packages will be UPDATED:

    alabaster:                0.7.10-py36hcd07829_0   --> 0.7.11-py36_0
    anaconda:                 5.2.0-py36_3            --> custom-py36h363777c_0
    astroid:                  1.6.3-py36_0            --> 1.6.5-py36_0
    astropy:                  3.0.2-py36h452e1ab_1    --> 3.0.3-py36hfa6e2cd_2
    babel:                    2.5.3-py36_0            --> 2.6.0-py36_0
    bitarray:                 0.8.1-py36hfa6e2cd_1    --> 0.8.2-py36hfa6e2cd_0
    bokeh:                    0.12.16-py36_0          --> 0.13.0-py36_0
    conda-build:              3.10.5-py36_0           --> 3.10.9-py36_0
    cython:                   0.28.2-py36hfa6e2cd_0   --> 0.28.3-py36hfa6e2cd_0
    dask:                     0.17.5-py36_0           --> 0.18.1-py36_0
    dask-core:                0.17.5-py36_0           --> 0.18.1-py36_0
    distributed:              1.21.8-py36_0           --> 1.22.0-py36_0
    flask-cors:               3.0.4-py36_0            --> 3.0.6-py36_0
    gevent:                   1.3.0-py36hfa6e2cd_0    --> 1.3.4-py36hfa6e2cd_0
    h5py:                     2.7.1-py36h3bdd7fb_2    --> 2.8.0-py36h3bdd7fb_0
    idna:                     2.6-py36h148d497_1      --> 2.7-py36_0
    intel-openmp:             2018.0.0-8              --> 2018.0.3-0
    llvmlite:                 0.23.1-py36hcacf6c6_0   --> 0.23.2-py36he51fdeb_0
    lxml:                     4.2.1-py36heafd4d3_0    --> 4.2.2-py36hef2cd61_0
    mkl:                      2018.0.2-1              --> 2018.0.3-1
    more-itertools:           4.1.0-py36_0            --> 4.2.0-py36_0
    numba:                    0.38.0-py36h830ac7b_0   --> 0.38.1-py36h830ac7b_0
    numpy:                    1.14.3-py36h9fa60d3_1   --> 1.14.5-py36h9fa60d3_0
    numpy-base:               1.14.3-py36h555522e_1   --> 1.14.5-py36h5c71026_0
    openpyxl:                 2.5.3-py36_0            --> 2.5.4-py36_0
    pandas:                   0.23.0-py36h830ac7b_0   --> 0.23.1-py36h830ac7b_0
    pandoc:                   1.19.2.1-hb2460c7_1     --> 2.2.1-h1a437c5_0
    parso:                    0.2.0-py36_0            --> 0.2.1-py36_0
    psutil:                   5.4.5-py36hfa6e2cd_0    --> 5.4.6-py36hfa6e2cd_0
    pycrypto:                 2.6.1-py36hfa6e2cd_8    --> 2.6.1-py36hfa6e2cd_9
    pycurl:                   7.43.0.1-py36h74b6da3_0 --> 7.43.0.2-py36h74b6da3_0
    pyflakes:                 1.6.0-py36h0b975d6_0    --> 2.0.0-py36_0
    pylint:                   1.8.4-py36_0            --> 1.9.2-py36_0
    pytables:                 3.4.3-py36he6f6034_1    --> 3.4.4-py36he6f6034_0
    pytest:                   3.5.1-py36_0            --> 3.6.2-py36_0
    pytest-astropy:           0.3.0-py36_0            --> 0.4.0-py36_0
    pytest-remotedata:        0.2.1-py36_0            --> 0.3.0-py36_0
    python:                   3.6.5-h0c2934d_0        --> 3.6.6-hea74fb7_0
    pywinpty:                 0.5.1-py36_0            --> 0.5.4-py36_0
    qt:                       5.9.5-vc14he4a7d60_0    --> 5.9.6-vc14h62aca36_0
    qtpy:                     1.4.1-py36_0            --> 1.4.2-py36_0
    requests:                 2.18.4-py36h4371aae_1   --> 2.19.1-py36_0
    ruamel_yaml:              0.15.35-py36hfa6e2cd_1  --> 0.15.40-py36hfa6e2cd_2
    scikit-image:             0.13.1-py36hfa6e2cd_1   --> 0.14.0-py36h6538335_1
    setuptools:               39.1.0-py36_0           --> 39.2.0-py36_0
    sortedcollections:        0.6.1-py36_0            --> 1.0.1-py36_0
    sortedcontainers:         1.5.10-py36_0           --> 2.0.4-py36_0
    sphinx:                   1.7.4-py36_0            --> 1.7.5-py36_0
    sphinxcontrib-websupport: 1.0.1-py36hb5e5916_1    --> 1.1.0-py36_1
    sqlalchemy:               1.2.7-py36ha85dd04_0    --> 1.2.8-py36hfa6e2cd_0
    sqlite:                   3.23.1-h35aae40_0       --> 3.24.0-h7602738_0
    urllib3:                  1.22-py36h276f60a_0     --> 1.23-py36_0
    xlsxwriter:               1.0.4-py36_0            --> 1.0.5-py36_0

Proceed ([y]/n)? y

Preparing transaction: done
Verifying transaction: failed

# >>>>>>>>>>>>>>>>>>>>>> ERROR REPORT <<<<<<<<<<<<<<<<<<<<<<

    Traceback (most recent call last):
      File "C:\ProgramData\Anaconda3\lib\site-packages\conda\exceptions.py", line 819, in __call__
        return func(*args, **kwargs)
      File "C:\ProgramData\Anaconda3\lib\site-packages\conda\cli\main.py", line 78, in _main
        exit_code = do_call(args, p)
      File "C:\ProgramData\Anaconda3\lib\site-packages\conda\cli\conda_argparse.py", line 77, in do_call
        exit_code = getattr(module, func_name)(args, parser)
      File "C:\ProgramData\Anaconda3\lib\site-packages\conda\cli\main_update.py", line 14, in execute
        install(args, parser, 'update')
      File "C:\ProgramData\Anaconda3\lib\site-packages\conda\cli\install.py", line 253, in install
        handle_txn(unlink_link_transaction, prefix, args, newenv)
      File "C:\ProgramData\Anaconda3\lib\site-packages\conda\cli\install.py", line 282, in handle_txn
        unlink_link_transaction.execute()
      File "C:\ProgramData\Anaconda3\lib\site-packages\conda\core\link.py", line 224, in execute
        self.verify()
      File "C:\ProgramData\Anaconda3\lib\site-packages\conda\common\io.py", line 46, in decorated
        return f(*args, **kwds)
      File "C:\ProgramData\Anaconda3\lib\site-packages\conda\core\link.py", line 211, in verify
        exceptions = self._verify(self.prefix_setups, self.prefix_action_groups)
      File "C:\ProgramData\Anaconda3\lib\site-packages\conda\core\link.py", line 481, in _verify
        cls._verify_transaction_level(prefix_setups),
      File "C:\ProgramData\Anaconda3\lib\site-packages\conda\core\link.py", line 476, in <genexpr>
        exceptions = tuple(exc for exc in concatv(
      File "C:\ProgramData\Anaconda3\lib\site-packages\conda\core\link.py", line 334, in _verify_individual_level
        error_result = axn.verify()
      File "C:\ProgramData\Anaconda3\lib\site-packages\conda\core\path_actions.py", line 292, in verify
        source_sha256 = compute_sha256sum(self.source_full_path)
      File "C:\ProgramData\Anaconda3\lib\site-packages\conda\gateways\disk\read.py", line 75, in compute_sha256sum
        return _digest_path('sha256', file_full_path)
      File "C:\ProgramData\Anaconda3\lib\site-packages\conda\gateways\disk\read.py", line 65, in _digest_path
        for chunk in iter(partial(fh.read, 8192), b''):
    PermissionError: [Errno 13] Permission denied

`$ C:\ProgramData\Anaconda3\Scripts\conda update --all`

  environment variables:
                 CIO_TEST=<not set>
        CONDA_DEFAULT_ENV=base
                CONDA_EXE=C:\ProgramData\Anaconda3\Scripts\conda.exe
             CONDA_PREFIX=C:\ProgramData\Anaconda3
    CONDA_PROMPT_MODIFIER=(base)
         CONDA_PYTHON_EXE=C:\ProgramData\Anaconda3\python.exe
               CONDA_ROOT=C:\ProgramData\Anaconda3
              CONDA_SHLVL=1
         DOCKER_CERT_PATH=C:\Users\Miki\.docker\machine\machines\default
DOCKER_TOOLBOX_INSTALL_PATH=C:\Program Files\Docker Toolbox
                 HOMEPATH=\Users\Miki
                 NO_PROXY=<set>
                     PATH=C:\ProgramData\Anaconda3;C:\ProgramData\Anaconda3\Library\mingw-w64\bi
                          n;C:\ProgramData\Anaconda3\Library\usr\bin;C:\ProgramData\Anaconda3\Li
                          brary\bin;C:\ProgramData\Anaconda3\Scripts;C:\ProgramData\Anaconda3\bi
                          n;C:\ProgramData\Anaconda3;C:\ProgramData\Anaconda3\Library\mingw-w64\
                          bin;C:\ProgramData\Anaconda3\Library\usr\bin;C:\ProgramData\Anaconda3\
                          Library\bin;C:\ProgramData\Anaconda3\Scripts;C:\Program
                          Files\Microsoft MPI\Bin\;C:\Program Files (x86)\Common Files\Oracle\Ja
                          va\javapath;C:\ProgramData\Oracle\Java\javapath;C:\WINDOWS\system32;C:
                          \WINDOWS;C:\WINDOWS\System32\Wbem;C:\WINDOWS\System32\WindowsPowerShel
                          l\v1.0\;C:\WINDOWS\System32\OpenSSH\;C:\Program Files\dotnet\;C:\Users
                          \Miki\Anaconda3;C:\Users\Miki\Anaconda3\Scripts;C:\Users\Miki\Anaconda
                          3\Library\bin;C:\Program Files\Microsoft SQL
                          Server\130\Tools\Binn\;C:\Users\Miki\AppData\Local\atom\bin;C:\Program
                          Files\gnuplot\bin;C:\VXIPNP\WinNT\Bin;C:\Program Files\Git\cmd;C:\User
                          s\Miki\AppData\Local\Microsoft\WindowsApps;C:\Program Files\Docker
                          Toolbox;C:\Program Files\CMake\bin
             PSMODULEPATH=C:\Program Files\WindowsPowerShell\Modules;C:\WINDOWS\system32\Windows
                          PowerShell\v1.0\Modules
         PYTHONIOENCODING=932
       REQUESTS_CA_BUNDLE=<not set>
            SSL_CERT_FILE=<not set>
    VBOX_MSI_INSTALL_PATH=C:\Program Files\Oracle\VirtualBox\
               VXIPNPPATH=C:\VXIPNP\

     active environment : base
    active env location : C:\ProgramData\Anaconda3
            shell level : 1
       user config file : C:\Users\Miki\.condarc
 populated config files : C:\Users\Miki\.condarc
          conda version : 4.5.4
    conda-build version : 3.10.5
         python version : 3.6.5.final.0
       base environment : C:\ProgramData\Anaconda3  (writable)
           channel URLs : https://repo.anaconda.com/pkgs/main/win-64
                          https://repo.anaconda.com/pkgs/main/noarch
                          https://repo.anaconda.com/pkgs/free/win-64
                          https://repo.anaconda.com/pkgs/free/noarch
                          https://repo.anaconda.com/pkgs/r/win-64
                          https://repo.anaconda.com/pkgs/r/noarch
                          https://repo.anaconda.com/pkgs/pro/win-64
                          https://repo.anaconda.com/pkgs/pro/noarch
                          https://repo.anaconda.com/pkgs/msys2/win-64
                          https://repo.anaconda.com/pkgs/msys2/noarch
          package cache : C:\ProgramData\Anaconda3\pkgs
                          C:\Users\Miki\AppData\Local\conda\conda\pkgs
       envs directories : C:\ProgramData\Anaconda3\envs
                          C:\Users\Miki\AppData\Local\conda\conda\envs
                          C:\Users\Miki\.conda\envs
               platform : win-64
             user-agent : conda/4.5.4 requests/2.18.4 CPython/3.6.5 Windows/10 Windows/10.0.17134
          administrator : True
             netrc file : None
           offline mode : False


An unexpected error has occurred. Conda has prepared the above report.
If submitted, this report will be used by core maintainers to improve
future releases of conda.
Would you like conda to send this report to the core maintainers?
[y/N]: