ERROR conda.core.link:_execute(502): An error occurred while uninstalling package 'defaults::anaconda-5.2.0-py36_3'.
PermissionError(13, 'アクセスが拒否されました。')
Attempting to roll back.

Rolling back transaction: done

PermissionError(13, 'アクセスが拒否されました。')

<状態>
このエラーが発生した場合, 同じPython.exeがPC上のファイルに存在していると考えられる.

<解決法>
